[32m2025-07-24 11:31:27 +0500[0m - dagster - [34mDEBUG[0m - __ASSET_JOB - 9e8334b9-8038-4024-8a58-2b6b27e4fe8f - 25606 - LOGS_CAPTURED - Started capturing logs in process (pid: 25606).
[32m2025-07-24 11:31:27 +0500[0m - dagster - [34mDEBUG[0m - __ASSET_JOB - 9e8334b9-8038-4024-8a58-2b6b27e4fe8f - 25606 - postgres_to_snowflake - STEP_START - Started execution of step "postgres_to_snowflake".
[32m2025-07-24 11:31:33 +0500[0m - dagster - [34mERROR[0m - [31m__ASSET_JOB - 9e8334b9-8038-4024-8a58-2b6b27e4fe8f - 25606 - postgres_to_snowflake - STEP_FAILURE - Execution of step "postgres_to_snowflake" failed.

dagster._core.errors.DagsterExecutionStepExecutionError: Error occurred while executing op "postgres_to_snowflake"::

dlt.pipeline.exceptions.PipelineStepFailed: Pipeline execution failed at `step=sync` with exception:

<class 'dlt.common.configuration.exceptions.ConfigFieldMissingException'>
Missing fields in configuration: ['database', 'username', 'host'] SnowflakeCredentials
	for field `database` the following (config providers, keys) were tried in order:
		(Environment Variables, POSTGRES_TO_SNOWFLAKE__DESTINATION__SNOWFLAKE__CREDENTIALS__DATABASE)
		(Environment Variables, POSTGRES_TO_SNOWFLAKE__DESTINATION__CREDENTIALS__DATABASE)
		(Environment Variables, POSTGRES_TO_SNOWFLAKE__CREDENTIALS__DATABASE)
		(Environment Variables, DESTINATION__SNOWFLAKE__CREDENTIALS__DATABASE)
		(Environment Variables, DESTINATION__CREDENTIALS__DATABASE)
		(Environment Variables, CREDENTIALS__DATABASE)
	for field `username` the following (config providers, keys) were tried in order:
		(Environment Variables, POSTGRES_TO_SNOWFLAKE__DESTINATION__SNOWFLAKE__CREDENTIALS__USERNAME)
		(Environment Variables, POSTGRES_TO_SNOWFLAKE__DESTINATION__CREDENTIALS__USERNAME)
		(Environment Variables, POSTGRES_TO_SNOWFLAKE__CREDENTIALS__USERNAME)
		(Environment Variables, DESTINATION__SNOWFLAKE__CREDENTIALS__USERNAME)
		(Environment Variables, DESTINATION__CREDENTIALS__USERNAME)
		(Environment Variables, CREDENTIALS__USERNAME)
	for field `host` the following (config providers, keys) were tried in order:
		(Environment Variables, POSTGRES_TO_SNOWFLAKE__DESTINATION__SNOWFLAKE__CREDENTIALS__HOST)
		(Environment Variables, POSTGRES_TO_SNOWFLAKE__DESTINATION__CREDENTIALS__HOST)
		(Environment Variables, POSTGRES_TO_SNOWFLAKE__CREDENTIALS__HOST)
		(Environment Variables, DESTINATION__SNOWFLAKE__CREDENTIALS__HOST)
		(Environment Variables, DESTINATION__CREDENTIALS__HOST)
		(Environment Variables, CREDENTIALS__HOST)

Provider `secrets.toml` loaded values from locations:
	- /home/user6/Project Dagster with dlt/my_source/my-source/.dlt/secrets.toml
	- /home/user6/.dlt/secrets.toml
WARNING: provider `secrets.toml` is empty. Locations (i.e., files) are missing or empty.
Provider `config.toml` loaded values from locations:
	- /home/user6/Project Dagster with dlt/my_source/my-source/.dlt/config.toml
	- /home/user6/.dlt/config.toml
WARNING: provider `config.toml` is empty. Locations (i.e., files) are missing or empty.

WARNING: Active pipeline `postgres_to_snowflake` used `/home/user6/Project Postgres/.dlt` directory to read config and secrets for the last successful run. Different directory `/home/user6/Project Dagster with dlt/my_source/my-source/.dlt` is used now which may be the reason for configuration not resolving.
If you keep `.dlt` folder with secret files in the same directory as your pipeline script but run your script or a dlt cli command from some other folder, secrets/configs will not be found.
Learn more: https://dlthub.com/docs/general-usage/credentials/


Stack Trace:
  File "/home/user6/Project Dagster with dlt/.venv/lib/python3.12/site-packages/dagster/_core/execution/plan/utils.py", line 57, in op_execution_error_boundary
    yield
  File "/home/user6/Project Dagster with dlt/.venv/lib/python3.12/site-packages/dagster/_utils/__init__.py", line 392, in iterate_with_context
    next_output = next(iterator)
                  ^^^^^^^^^^^^^^
  File "/home/user6/Project Dagster with dlt/.venv/lib/python3.12/site-packages/dagster/_core/execution/plan/compute_generator.py", line 137, in _coerce_op_compute_fn_to_iterator
    result = invoke_compute_fn(
             ^^^^^^^^^^^^^^^^^^
  File "/home/user6/Project Dagster with dlt/.venv/lib/python3.12/site-packages/dagster/_core/execution/plan/compute_generator.py", line 117, in invoke_compute_fn
    return fn(context, **args_to_pass) if context_arg_provided else fn(**args_to_pass)
                                                                    ^^^^^^^^^^^^^^^^^^
  File "/home/user6/Project Dagster with dlt/my_source/my-source/my_source/assets.py", line 18, in postgres_to_snowflake
    load_info = pipeline.run(source, write_disposition="replace")
                ^^^^^^^^^^^^^^^^^^^^^^^^^^^^^^^^^^^^^^^^^^^^^^^^^
  File "/home/user6/Project Dagster with dlt/.venv/lib/python3.12/site-packages/dlt/pipeline/pipeline.py", line 231, in _wrap
    step_info = f(self, *args, **kwargs)
                ^^^^^^^^^^^^^^^^^^^^^^^^
  File "/home/user6/Project Dagster with dlt/.venv/lib/python3.12/site-packages/dlt/pipeline/pipeline.py", line 280, in _wrap
    return f(self, *args, **kwargs)
           ^^^^^^^^^^^^^^^^^^^^^^^^
  File "/home/user6/Project Dagster with dlt/.venv/lib/python3.12/site-packages/dlt/pipeline/pipeline.py", line 713, in run
    self._sync_destination(destination, staging, dataset_name)
  File "/home/user6/Project Dagster with dlt/.venv/lib/python3.12/site-packages/dlt/pipeline/pipeline.py", line 185, in _wrap
    rv = f(self, *args, **kwargs)
         ^^^^^^^^^^^^^^^^^^^^^^^^
  File "/home/user6/Project Dagster with dlt/.venv/lib/python3.12/site-packages/dlt/pipeline/pipeline.py", line 882, in _sync_destination
    raise PipelineStepFailed(self, "sync", None, ex, None) from ex

The above exception was caused by the following exception:
dlt.common.configuration.exceptions.ConfigFieldMissingException: Missing fields in configuration: ['database', 'username', 'host'] SnowflakeCredentials
	for field `database` the following (config providers, keys) were tried in order:
		(Environment Variables, POSTGRES_TO_SNOWFLAKE__DESTINATION__SNOWFLAKE__CREDENTIALS__DATABASE)
		(Environment Variables, POSTGRES_TO_SNOWFLAKE__DESTINATION__CREDENTIALS__DATABASE)
		(Environment Variables, POSTGRES_TO_SNOWFLAKE__CREDENTIALS__DATABASE)
		(Environment Variables, DESTINATION__SNOWFLAKE__CREDENTIALS__DATABASE)
		(Environment Variables, DESTINATION__CREDENTIALS__DATABASE)
		(Environment Variables, CREDENTIALS__DATABASE)
	for field `username` the following (config providers, keys) were tried in order:
		(Environment Variables, POSTGRES_TO_SNOWFLAKE__DESTINATION__SNOWFLAKE__CREDENTIALS__USERNAME)
		(Environment Variables, POSTGRES_TO_SNOWFLAKE__DESTINATION__CREDENTIALS__USERNAME)
		(Environment Variables, POSTGRES_TO_SNOWFLAKE__CREDENTIALS__USERNAME)
		(Environment Variables, DESTINATION__SNOWFLAKE__CREDENTIALS__USERNAME)
		(Environment Variables, DESTINATION__CREDENTIALS__USERNAME)
		(Environment Variables, CREDENTIALS__USERNAME)
	for field `host` the following (config providers, keys) were tried in order:
		(Environment Variables, POSTGRES_TO_SNOWFLAKE__DESTINATION__SNOWFLAKE__CREDENTIALS__HOST)
		(Environment Variables, POSTGRES_TO_SNOWFLAKE__DESTINATION__CREDENTIALS__HOST)
		(Environment Variables, POSTGRES_TO_SNOWFLAKE__CREDENTIALS__HOST)
		(Environment Variables, DESTINATION__SNOWFLAKE__CREDENTIALS__HOST)
		(Environment Variables, DESTINATION__CREDENTIALS__HOST)
		(Environment Variables, CREDENTIALS__HOST)

Provider `secrets.toml` loaded values from locations:
	- /home/user6/Project Dagster with dlt/my_source/my-source/.dlt/secrets.toml
	- /home/user6/.dlt/secrets.toml
WARNING: provider `secrets.toml` is empty. Locations (i.e., files) are missing or empty.
Provider `config.toml` loaded values from locations:
	- /home/user6/Project Dagster with dlt/my_source/my-source/.dlt/config.toml
	- /home/user6/.dlt/config.toml
WARNING: provider `config.toml` is empty. Locations (i.e., files) are missing or empty.

WARNING: Active pipeline `postgres_to_snowflake` used `/home/user6/Project Postgres/.dlt` directory to read config and secrets for the last successful run. Different directory `/home/user6/Project Dagster with dlt/my_source/my-source/.dlt` is used now which may be the reason for configuration not resolving.
If you keep `.dlt` folder with secret files in the same directory as your pipeline script but run your script or a dlt cli command from some other folder, secrets/configs will not be found.
Learn more: https://dlthub.com/docs/general-usage/credentials/


Stack Trace:
  File "/home/user6/Project Dagster with dlt/.venv/lib/python3.12/site-packages/dlt/pipeline/pipeline.py", line 786, in _sync_destination
    remote_state = self._restore_state_from_destination()
                   ^^^^^^^^^^^^^^^^^^^^^^^^^^^^^^^^^^^^^^
  File "/home/user6/Project Dagster with dlt/.venv/lib/python3.12/site-packages/dlt/pipeline/pipeline.py", line 1589, in _restore_state_from_destination
    with self._get_destination_clients(schema)[0] as job_client:
         ^^^^^^^^^^^^^^^^^^^^^^^^^^^^^^^^^^^^^
  File "/home/user6/Project Dagster with dlt/.venv/lib/python3.12/site-packages/dlt/pipeline/pipeline.py", line 1337, in _get_destination_clients
    destination_client, staging_client = get_destination_clients(
                                         ^^^^^^^^^^^^^^^^^^^^^^^^
  File "/home/user6/Project Dagster with dlt/.venv/lib/python3.12/site-packages/dlt/destinations/dataset/utils.py", line 85, in get_destination_clients
    client = destination.client(schema, initial_config)
             ^^^^^^^^^^^^^^^^^^^^^^^^^^^^^^^^^^^^^^^^^^
  File "/home/user6/Project Dagster with dlt/.venv/lib/python3.12/site-packages/dlt/common/destination/reference.py", line 173, in client
    config = self.configuration(initial_config)
             ^^^^^^^^^^^^^^^^^^^^^^^^^^^^^^^^^^
  File "/home/user6/Project Dagster with dlt/.venv/lib/python3.12/site-packages/dlt/common/destination/reference.py", line 160, in configuration
    config = resolve_configuration(
             ^^^^^^^^^^^^^^^^^^^^^^
  File "/home/user6/Project Dagster with dlt/.venv/lib/python3.12/site-packages/dlt/common/configuration/resolve.py", line 75, in resolve_configuration
    return _resolve_configuration(config, sections, (), explicit_value, accept_partial)
           ^^^^^^^^^^^^^^^^^^^^^^^^^^^^^^^^^^^^^^^^^^^^^^^^^^^^^^^^^^^^^^^^^^^^^^^^^^^^
  File "/home/user6/Project Dagster with dlt/.venv/lib/python3.12/site-packages/dlt/common/configuration/resolve.py", line 181, in _resolve_configuration
    _resolve_config_fields(
  File "/home/user6/Project Dagster with dlt/.venv/lib/python3.12/site-packages/dlt/common/configuration/resolve.py", line 302, in _resolve_config_fields
    current_value, traces = _resolve_config_field(
                            ^^^^^^^^^^^^^^^^^^^^^^
  File "/home/user6/Project Dagster with dlt/.venv/lib/python3.12/site-packages/dlt/common/configuration/resolve.py", line 415, in _resolve_config_field
    value = _resolve_configuration(
            ^^^^^^^^^^^^^^^^^^^^^^^
  File "/home/user6/Project Dagster with dlt/.venv/lib/python3.12/site-packages/dlt/common/configuration/resolve.py", line 181, in _resolve_configuration
    _resolve_config_fields(
  File "/home/user6/Project Dagster with dlt/.venv/lib/python3.12/site-packages/dlt/common/configuration/resolve.py", line 329, in _resolve_config_fields
    raise ConfigFieldMissingException(type(config).__name__, unresolved_fields)
[0m
