[32m2025-07-24 11:55:22 +0500[0m - dagster - [34mDEBUG[0m - __ASSET_JOB - 9e073592-dc46-445c-9ec4-64604c5967a0 - 63309 - LOGS_CAPTURED - Started capturing logs in process (pid: 63309).
[32m2025-07-24 11:55:22 +0500[0m - dagster - [34mDEBUG[0m - __ASSET_JOB - 9e073592-dc46-445c-9ec4-64604c5967a0 - 63309 - postgres_to_snowflake - STEP_START - Started execution of step "postgres_to_snowflake".
[32m2025-07-24 11:55:35 +0500[0m - dagster - [34mERROR[0m - [31m__ASSET_JOB - 9e073592-dc46-445c-9ec4-64604c5967a0 - 63309 - postgres_to_snowflake - STEP_FAILURE - Execution of step "postgres_to_snowflake" failed.

dagster._core.errors.DagsterExecutionStepExecutionError: Error occurred while executing op "postgres_to_snowflake"::

dlt.pipeline.exceptions.PipelineStepFailed: Pipeline execution failed at `step=sync` with exception:

<class 'snowflake.connector.errors.OperationalError'>
250001: Could not connect to Snowflake backend after 2 attempt(s).Aborting
Verify that the hostnames and port numbers in SYSTEM$ALLOWLIST are added to your firewall's allowed list.
To further troubleshoot your connection you may reference the following article: https://docs.snowflake.com/en/user-guide/client-connectivity-troubleshooting/overview.

Stack Trace:
  File "/home/user6/Project Dagster with dlt/.venv/lib/python3.12/site-packages/dagster/_core/execution/plan/utils.py", line 57, in op_execution_error_boundary
    yield
  File "/home/user6/Project Dagster with dlt/.venv/lib/python3.12/site-packages/dagster/_utils/__init__.py", line 392, in iterate_with_context
    next_output = next(iterator)
                  ^^^^^^^^^^^^^^
  File "/home/user6/Project Dagster with dlt/.venv/lib/python3.12/site-packages/dagster/_core/execution/plan/compute_generator.py", line 137, in _coerce_op_compute_fn_to_iterator
    result = invoke_compute_fn(
             ^^^^^^^^^^^^^^^^^^
  File "/home/user6/Project Dagster with dlt/.venv/lib/python3.12/site-packages/dagster/_core/execution/plan/compute_generator.py", line 117, in invoke_compute_fn
    return fn(context, **args_to_pass) if context_arg_provided else fn(**args_to_pass)
                                                                    ^^^^^^^^^^^^^^^^^^
  File "/home/user6/Project Dagster with dlt/my_source/my-source/my_source/assets.py", line 18, in postgres_to_snowflake
    load_info = pipeline.run(source, write_disposition="replace")
                ^^^^^^^^^^^^^^^^^^^^^^^^^^^^^^^^^^^^^^^^^^^^^^^^^
  File "/home/user6/Project Dagster with dlt/.venv/lib/python3.12/site-packages/dlt/pipeline/pipeline.py", line 231, in _wrap
    step_info = f(self, *args, **kwargs)
                ^^^^^^^^^^^^^^^^^^^^^^^^
  File "/home/user6/Project Dagster with dlt/.venv/lib/python3.12/site-packages/dlt/pipeline/pipeline.py", line 280, in _wrap
    return f(self, *args, **kwargs)
           ^^^^^^^^^^^^^^^^^^^^^^^^
  File "/home/user6/Project Dagster with dlt/.venv/lib/python3.12/site-packages/dlt/pipeline/pipeline.py", line 713, in run
    self._sync_destination(destination, staging, dataset_name)
  File "/home/user6/Project Dagster with dlt/.venv/lib/python3.12/site-packages/dlt/pipeline/pipeline.py", line 185, in _wrap
    rv = f(self, *args, **kwargs)
         ^^^^^^^^^^^^^^^^^^^^^^^^
  File "/home/user6/Project Dagster with dlt/.venv/lib/python3.12/site-packages/dlt/pipeline/pipeline.py", line 882, in _sync_destination
    raise PipelineStepFailed(self, "sync", None, ex, None) from ex

The above exception was caused by the following exception:
snowflake.connector.errors.OperationalError: 250001: Could not connect to Snowflake backend after 2 attempt(s).Aborting
Verify that the hostnames and port numbers in SYSTEM$ALLOWLIST are added to your firewall's allowed list.
To further troubleshoot your connection you may reference the following article: https://docs.snowflake.com/en/user-guide/client-connectivity-troubleshooting/overview.

Stack Trace:
  File "/home/user6/Project Dagster with dlt/.venv/lib/python3.12/site-packages/dlt/pipeline/pipeline.py", line 786, in _sync_destination
    remote_state = self._restore_state_from_destination()
                   ^^^^^^^^^^^^^^^^^^^^^^^^^^^^^^^^^^^^^^
  File "/home/user6/Project Dagster with dlt/.venv/lib/python3.12/site-packages/dlt/pipeline/pipeline.py", line 1589, in _restore_state_from_destination
    with self._get_destination_clients(schema)[0] as job_client:
  File "/home/user6/Project Dagster with dlt/.venv/lib/python3.12/site-packages/dlt/destinations/job_client_impl.py", line 421, in __enter__
    self.sql_client.open_connection()
  File "/home/user6/Project Dagster with dlt/.venv/lib/python3.12/site-packages/dlt/destinations/impl/snowflake/sql_client.py", line 72, in open_connection
    self._conn = snowflake_lib.connect(
                 ^^^^^^^^^^^^^^^^^^^^^^
  File "/home/user6/Project Dagster with dlt/.venv/lib/python3.12/site-packages/snowflake/connector/__init__.py", line 54, in Connect
    return SnowflakeConnection(**kwargs)
           ^^^^^^^^^^^^^^^^^^^^^^^^^^^^^
  File "/home/user6/Project Dagster with dlt/.venv/lib/python3.12/site-packages/snowflake/connector/connection.py", line 554, in __init__
    self.connect(**kwargs)
  File "/home/user6/Project Dagster with dlt/.venv/lib/python3.12/site-packages/snowflake/connector/connection.py", line 911, in connect
    self.__open_connection()
  File "/home/user6/Project Dagster with dlt/.venv/lib/python3.12/site-packages/snowflake/connector/connection.py", line 1312, in __open_connection
    self.authenticate_with_retry(self.auth_class)
  File "/home/user6/Project Dagster with dlt/.venv/lib/python3.12/site-packages/snowflake/connector/connection.py", line 1637, in authenticate_with_retry
    self._authenticate(auth_instance)
  File "/home/user6/Project Dagster with dlt/.venv/lib/python3.12/site-packages/snowflake/connector/connection.py", line 1715, in _authenticate
    raise auth_op from e
  File "/home/user6/Project Dagster with dlt/.venv/lib/python3.12/site-packages/snowflake/connector/connection.py", line 1690, in _authenticate
    auth_instance.handle_timeout(
  File "/home/user6/Project Dagster with dlt/.venv/lib/python3.12/site-packages/snowflake/connector/auth/by_plugin.py", line 212, in handle_timeout
    raise error

The above exception was caused by the following exception:
snowflake.connector.errors.OperationalError: 250003: Hit non-retryable SSL error, HTTPSConnectionPool(host='elkpblo-qp13448.snowflakecomputing.com.snowflakecomputing.com', port=443): Max retries exceeded with url: /session/v1/login-request?request_id=60e1c913-9ce0-4af5-b7db-d63f0a98fc4c&databaseName=SNOWFLAKE_LEARNING_DB&schemaName=%22POSTGRES_ALL_DATA_TEST%22&warehouse=COMPUTE_WH&roleName=ACCOUNTADMIN&request_guid=ef186f0e-02c8-4771-8052-da4b82fa45a2 (Caused by SSLError(CertificateError("hostname 'elkpblo-qp13448.snowflakecomputing.com.snowflakecomputing.com' doesn't match either of '*.prod3.us-west-2.snowflakecomputing.com', '*.us-west-2.snowflakecomputing.com', '*.global.snowflakecomputing.com', '*.snowflakecomputing.com', '*.prod3.us-west-2.aws.snowflakecomputing.com'"))).
Verify that the hostnames and port numbers in SYSTEM$ALLOWLIST are added to your firewall's allowed list.
To further troubleshoot your connection you may reference the following article: https://docs.snowflake.com/en/user-guide/client-connectivity-troubleshooting/overview.

Stack Trace:
  File "/home/user6/Project Dagster with dlt/.venv/lib/python3.12/site-packages/snowflake/connector/connection.py", line 1669, in _authenticate
    auth.authenticate(
  File "/home/user6/Project Dagster with dlt/.venv/lib/python3.12/site-packages/snowflake/connector/auth/_auth.py", line 226, in authenticate
    ret = self._rest._post_request(
          ^^^^^^^^^^^^^^^^^^^^^^^^^
  File "/home/user6/Project Dagster with dlt/.venv/lib/python3.12/site-packages/snowflake/connector/network.py", line 805, in _post_request
    ret = self.fetch(
          ^^^^^^^^^^^
  File "/home/user6/Project Dagster with dlt/.venv/lib/python3.12/site-packages/snowflake/connector/network.py", line 924, in fetch
    ret = self._request_exec_wrapper(
          ^^^^^^^^^^^^^^^^^^^^^^^^^^^
  File "/home/user6/Project Dagster with dlt/.venv/lib/python3.12/site-packages/snowflake/connector/network.py", line 1054, in _request_exec_wrapper
    raise e
  File "/home/user6/Project Dagster with dlt/.venv/lib/python3.12/site-packages/snowflake/connector/network.py", line 975, in _request_exec_wrapper
    return_object = self._request_exec(
                    ^^^^^^^^^^^^^^^^^^^
  File "/home/user6/Project Dagster with dlt/.venv/lib/python3.12/site-packages/snowflake/connector/network.py", line 1219, in _request_exec
    Error.errorhandler_wrapper(
  File "/home/user6/Project Dagster with dlt/.venv/lib/python3.12/site-packages/snowflake/connector/errors.py", line 279, in errorhandler_wrapper
    handed_over = Error.hand_to_other_handler(
                  ^^^^^^^^^^^^^^^^^^^^^^^^^^^^
  File "/home/user6/Project Dagster with dlt/.venv/lib/python3.12/site-packages/snowflake/connector/errors.py", line 337, in hand_to_other_handler
    connection.errorhandler(connection, cursor, error_class, error_value)
  File "/home/user6/Project Dagster with dlt/.venv/lib/python3.12/site-packages/snowflake/connector/errors.py", line 210, in default_errorhandler
    raise error_class(

The above exception occurred during handling of the following exception:
snowflake.connector.vendored.requests.exceptions.SSLError: HTTPSConnectionPool(host='elkpblo-qp13448.snowflakecomputing.com.snowflakecomputing.com', port=443): Max retries exceeded with url: /session/v1/login-request?request_id=60e1c913-9ce0-4af5-b7db-d63f0a98fc4c&databaseName=SNOWFLAKE_LEARNING_DB&schemaName=%22POSTGRES_ALL_DATA_TEST%22&warehouse=COMPUTE_WH&roleName=ACCOUNTADMIN&request_guid=ef186f0e-02c8-4771-8052-da4b82fa45a2 (Caused by SSLError(CertificateError("hostname 'elkpblo-qp13448.snowflakecomputing.com.snowflakecomputing.com' doesn't match either of '*.prod3.us-west-2.snowflakecomputing.com', '*.us-west-2.snowflakecomputing.com', '*.global.snowflakecomputing.com', '*.snowflakecomputing.com', '*.prod3.us-west-2.aws.snowflakecomputing.com'")))

Stack Trace:
  File "/home/user6/Project Dagster with dlt/.venv/lib/python3.12/site-packages/snowflake/connector/network.py", line 1149, in _request_exec
    raw_ret = session.request(
              ^^^^^^^^^^^^^^^^
  File "/home/user6/Project Dagster with dlt/.venv/lib/python3.12/site-packages/snowflake/connector/vendored/requests/sessions.py", line 589, in request
    resp = self.send(prep, **send_kwargs)
           ^^^^^^^^^^^^^^^^^^^^^^^^^^^^^^
  File "/home/user6/Project Dagster with dlt/.venv/lib/python3.12/site-packages/snowflake/connector/vendored/requests/sessions.py", line 703, in send
    r = adapter.send(request, **kwargs)
        ^^^^^^^^^^^^^^^^^^^^^^^^^^^^^^^
  File "/home/user6/Project Dagster with dlt/.venv/lib/python3.12/site-packages/snowflake/connector/vendored/requests/adapters.py", line 516, in send
    raise SSLError(e, request=request)

The above exception occurred during handling of the following exception:
snowflake.connector.vendored.urllib3.exceptions.MaxRetryError: HTTPSConnectionPool(host='elkpblo-qp13448.snowflakecomputing.com.snowflakecomputing.com', port=443): Max retries exceeded with url: /session/v1/login-request?request_id=60e1c913-9ce0-4af5-b7db-d63f0a98fc4c&databaseName=SNOWFLAKE_LEARNING_DB&schemaName=%22POSTGRES_ALL_DATA_TEST%22&warehouse=COMPUTE_WH&roleName=ACCOUNTADMIN&request_guid=ef186f0e-02c8-4771-8052-da4b82fa45a2 (Caused by SSLError(CertificateError("hostname 'elkpblo-qp13448.snowflakecomputing.com.snowflakecomputing.com' doesn't match either of '*.prod3.us-west-2.snowflakecomputing.com', '*.us-west-2.snowflakecomputing.com', '*.global.snowflakecomputing.com', '*.snowflakecomputing.com', '*.prod3.us-west-2.aws.snowflakecomputing.com'")))

Stack Trace:
  File "/home/user6/Project Dagster with dlt/.venv/lib/python3.12/site-packages/snowflake/connector/vendored/requests/adapters.py", line 485, in send
    resp = conn.urlopen(
           ^^^^^^^^^^^^^
  File "/home/user6/Project Dagster with dlt/.venv/lib/python3.12/site-packages/snowflake/connector/vendored/urllib3/connectionpool.py", line 827, in urlopen
    return self.urlopen(
           ^^^^^^^^^^^^^
  File "/home/user6/Project Dagster with dlt/.venv/lib/python3.12/site-packages/snowflake/connector/vendored/urllib3/connectionpool.py", line 799, in urlopen
    retries = retries.increment(
              ^^^^^^^^^^^^^^^^^^
  File "/home/user6/Project Dagster with dlt/.venv/lib/python3.12/site-packages/snowflake/connector/vendored/urllib3/util/retry.py", line 592, in increment
    raise MaxRetryError(_pool, url, error or ResponseError(cause))

The above exception occurred during handling of the following exception:
snowflake.connector.vendored.urllib3.util.ssl_match_hostname.CertificateError: hostname 'elkpblo-qp13448.snowflakecomputing.com.snowflakecomputing.com' doesn't match either of '*.prod3.us-west-2.snowflakecomputing.com', '*.us-west-2.snowflakecomputing.com', '*.global.snowflakecomputing.com', '*.snowflakecomputing.com', '*.prod3.us-west-2.aws.snowflakecomputing.com'

Stack Trace:
  File "/home/user6/Project Dagster with dlt/.venv/lib/python3.12/site-packages/snowflake/connector/vendored/urllib3/connectionpool.py", line 715, in urlopen
    httplib_response = self._make_request(
                       ^^^^^^^^^^^^^^^^^^^
  File "/home/user6/Project Dagster with dlt/.venv/lib/python3.12/site-packages/snowflake/connector/vendored/urllib3/connectionpool.py", line 404, in _make_request
    self._validate_conn(conn)
  File "/home/user6/Project Dagster with dlt/.venv/lib/python3.12/site-packages/snowflake/connector/vendored/urllib3/connectionpool.py", line 1058, in _validate_conn
    conn.connect()
  File "/home/user6/Project Dagster with dlt/.venv/lib/python3.12/site-packages/snowflake/connector/vendored/urllib3/connection.py", line 472, in connect
    _match_hostname(cert, self.assert_hostname or server_hostname)
  File "/home/user6/Project Dagster with dlt/.venv/lib/python3.12/site-packages/snowflake/connector/vendored/urllib3/connection.py", line 545, in _match_hostname
    match_hostname(cert, asserted_hostname)
  File "/home/user6/Project Dagster with dlt/.venv/lib/python3.12/site-packages/snowflake/connector/vendored/urllib3/util/ssl_match_hostname.py", line 150, in match_hostname
    raise CertificateError(
[0m
