[32m2025-07-24 12:24:48 +0500[0m - dagster - [34mDEBUG[0m - __ASSET_JOB - 381c75c1-f0c2-4294-8bbb-19f893d3a9a2 - 106547 - LOGS_CAPTURED - Started capturing logs in process (pid: 106547).
[32m2025-07-24 12:24:48 +0500[0m - dagster - [34mDEBUG[0m - __ASSET_JOB - 381c75c1-f0c2-4294-8bbb-19f893d3a9a2 - 106547 - load_postgres_data - STEP_START - Started execution of step "load_postgres_data".
2025-07-24 12:25:15,910|[ERROR]|106547|124912320628416|dlt|load.py|w_run_job:247|Transient exception in job employees.967d5337e4.jsonl in file /home/user6/.dlt/pipelines/postgres_to_snowflake/load/normalized/1753341887.5317843/started_jobs/employees.967d5337e4.0.jsonl
Traceback (most recent call last):
  File "/home/user6/Project Dagster with dlt/.venv/lib/python3.12/site-packages/dlt/destinations/sql_client.py", line 443, in _wrap_gen
    return (yield from f(self, *args, **kwargs))
            ^^^^^^^^^^^^^^^^^^^^^^^^^^^^^^^^^^^
  File "/home/user6/Project Dagster with dlt/.venv/lib/python3.12/site-packages/dlt/destinations/impl/snowflake/sql_client.py", line 138, in execute_query
    raise outer
  File "/home/user6/Project Dagster with dlt/.venv/lib/python3.12/site-packages/dlt/destinations/impl/snowflake/sql_client.py", line 130, in execute_query
    curr.execute(query, db_args, num_statements=0)
  File "/home/user6/Project Dagster with dlt/.venv/lib/python3.12/site-packages/snowflake/connector/cursor.py", line 1090, in execute
    sf_file_transfer_agent.execute()
  File "/home/user6/Project Dagster with dlt/.venv/lib/python3.12/site-packages/snowflake/connector/file_transfer_agent.py", line 393, in execute
    self._init_file_metadata()
  File "/home/user6/Project Dagster with dlt/.venv/lib/python3.12/site-packages/snowflake/connector/file_transfer_agent.py", line 999, in _init_file_metadata
    Error.errorhandler_wrapper(
  File "/home/user6/Project Dagster with dlt/.venv/lib/python3.12/site-packages/snowflake/connector/errors.py", line 279, in errorhandler_wrapper
    handed_over = Error.hand_to_other_handler(
                  ^^^^^^^^^^^^^^^^^^^^^^^^^^^^
  File "/home/user6/Project Dagster with dlt/.venv/lib/python3.12/site-packages/snowflake/connector/errors.py", line 334, in hand_to_other_handler
    cursor.errorhandler(connection, cursor, error_class, error_value)
  File "/home/user6/Project Dagster with dlt/.venv/lib/python3.12/site-packages/snowflake/connector/errors.py", line 210, in default_errorhandler
    raise error_class(
snowflake.connector.errors.ProgrammingError: 253006: File doesn't exist: ['/home/user6/.dlt/pipelines/postgres_to_snowflake/load/normalized/1753341887.5317843/started_jobs/employees.967d5337e4.0.jsonl']

During handling of the above exception, another exception occurred:

Traceback (most recent call last):
  File "/home/user6/Project Dagster with dlt/.venv/lib/python3.12/site-packages/dlt/common/destination/client.py", line 406, in run_managed
    self.run()
  File "/home/user6/Project Dagster with dlt/.venv/lib/python3.12/site-packages/dlt/destinations/impl/snowflake/snowflake.py", line 109, in run
    self._sql_client.execute_sql(
  File "/home/user6/Project Dagster with dlt/.venv/lib/python3.12/site-packages/dlt/destinations/impl/snowflake/sql_client.py", line 116, in execute_sql
    with self.execute_query(sql, *args, **kwargs) as curr:
  File "/usr/lib/python3.12/contextlib.py", line 137, in __enter__
    return next(self.gen)
           ^^^^^^^^^^^^^^
  File "/home/user6/Project Dagster with dlt/.venv/lib/python3.12/site-packages/dlt/destinations/sql_client.py", line 445, in _wrap_gen
    raise self._make_database_exception(ex)
dlt.destinations.exceptions.DatabaseTransientException: 253006: File doesn't exist: ['/home/user6/.dlt/pipelines/postgres_to_snowflake/load/normalized/1753341887.5317843/started_jobs/employees.967d5337e4.0.jsonl']
2025-07-24 12:25:16,023|[ERROR]|106547|124912303843008|dlt|load.py|w_run_job:247|Transient exception in job stores.5702041419.jsonl in file /home/user6/.dlt/pipelines/postgres_to_snowflake/load/normalized/1753341887.5317843/started_jobs/stores.5702041419.0.jsonl
Traceback (most recent call last):
  File "/home/user6/Project Dagster with dlt/.venv/lib/python3.12/site-packages/dlt/destinations/sql_client.py", line 443, in _wrap_gen
    return (yield from f(self, *args, **kwargs))
            ^^^^^^^^^^^^^^^^^^^^^^^^^^^^^^^^^^^
  File "/home/user6/Project Dagster with dlt/.venv/lib/python3.12/site-packages/dlt/destinations/impl/snowflake/sql_client.py", line 138, in execute_query
    raise outer
  File "/home/user6/Project Dagster with dlt/.venv/lib/python3.12/site-packages/dlt/destinations/impl/snowflake/sql_client.py", line 130, in execute_query
    curr.execute(query, db_args, num_statements=0)
  File "/home/user6/Project Dagster with dlt/.venv/lib/python3.12/site-packages/snowflake/connector/cursor.py", line 1090, in execute
    sf_file_transfer_agent.execute()
  File "/home/user6/Project Dagster with dlt/.venv/lib/python3.12/site-packages/snowflake/connector/file_transfer_agent.py", line 393, in execute
    self._init_file_metadata()
  File "/home/user6/Project Dagster with dlt/.venv/lib/python3.12/site-packages/snowflake/connector/file_transfer_agent.py", line 999, in _init_file_metadata
    Error.errorhandler_wrapper(
  File "/home/user6/Project Dagster with dlt/.venv/lib/python3.12/site-packages/snowflake/connector/errors.py", line 279, in errorhandler_wrapper
    handed_over = Error.hand_to_other_handler(
                  ^^^^^^^^^^^^^^^^^^^^^^^^^^^^
  File "/home/user6/Project Dagster with dlt/.venv/lib/python3.12/site-packages/snowflake/connector/errors.py", line 334, in hand_to_other_handler
    cursor.errorhandler(connection, cursor, error_class, error_value)
  File "/home/user6/Project Dagster with dlt/.venv/lib/python3.12/site-packages/snowflake/connector/errors.py", line 210, in default_errorhandler
    raise error_class(
snowflake.connector.errors.ProgrammingError: 253006: File doesn't exist: ['/home/user6/.dlt/pipelines/postgres_to_snowflake/load/normalized/1753341887.5317843/started_jobs/stores.5702041419.0.jsonl']

During handling of the above exception, another exception occurred:

Traceback (most recent call last):
  File "/home/user6/Project Dagster with dlt/.venv/lib/python3.12/site-packages/dlt/common/destination/client.py", line 406, in run_managed
    self.run()
  File "/home/user6/Project Dagster with dlt/.venv/lib/python3.12/site-packages/dlt/destinations/impl/snowflake/snowflake.py", line 109, in run
    self._sql_client.execute_sql(
  File "/home/user6/Project Dagster with dlt/.venv/lib/python3.12/site-packages/dlt/destinations/impl/snowflake/sql_client.py", line 116, in execute_sql
    with self.execute_query(sql, *args, **kwargs) as curr:
  File "/usr/lib/python3.12/contextlib.py", line 137, in __enter__
    return next(self.gen)
           ^^^^^^^^^^^^^^
  File "/home/user6/Project Dagster with dlt/.venv/lib/python3.12/site-packages/dlt/destinations/sql_client.py", line 445, in _wrap_gen
    raise self._make_database_exception(ex)
dlt.destinations.exceptions.DatabaseTransientException: 253006: File doesn't exist: ['/home/user6/.dlt/pipelines/postgres_to_snowflake/load/normalized/1753341887.5317843/started_jobs/stores.5702041419.0.jsonl']
2025-07-24 12:25:16,058|[ERROR]|106547|124912312235712|dlt|load.py|w_run_job:247|Transient exception in job items.5536d106e7.jsonl in file /home/user6/.dlt/pipelines/postgres_to_snowflake/load/normalized/1753341887.5317843/started_jobs/items.5536d106e7.0.jsonl
Traceback (most recent call last):
  File "/home/user6/Project Dagster with dlt/.venv/lib/python3.12/site-packages/dlt/destinations/sql_client.py", line 443, in _wrap_gen
    return (yield from f(self, *args, **kwargs))
            ^^^^^^^^^^^^^^^^^^^^^^^^^^^^^^^^^^^
  File "/home/user6/Project Dagster with dlt/.venv/lib/python3.12/site-packages/dlt/destinations/impl/snowflake/sql_client.py", line 138, in execute_query
    raise outer
  File "/home/user6/Project Dagster with dlt/.venv/lib/python3.12/site-packages/dlt/destinations/impl/snowflake/sql_client.py", line 130, in execute_query
    curr.execute(query, db_args, num_statements=0)
  File "/home/user6/Project Dagster with dlt/.venv/lib/python3.12/site-packages/snowflake/connector/cursor.py", line 1090, in execute
    sf_file_transfer_agent.execute()
  File "/home/user6/Project Dagster with dlt/.venv/lib/python3.12/site-packages/snowflake/connector/file_transfer_agent.py", line 393, in execute
    self._init_file_metadata()
  File "/home/user6/Project Dagster with dlt/.venv/lib/python3.12/site-packages/snowflake/connector/file_transfer_agent.py", line 999, in _init_file_metadata
    Error.errorhandler_wrapper(
  File "/home/user6/Project Dagster with dlt/.venv/lib/python3.12/site-packages/snowflake/connector/errors.py", line 279, in errorhandler_wrapper
    handed_over = Error.hand_to_other_handler(
                  ^^^^^^^^^^^^^^^^^^^^^^^^^^^^
  File "/home/user6/Project Dagster with dlt/.venv/lib/python3.12/site-packages/snowflake/connector/errors.py", line 334, in hand_to_other_handler
    cursor.errorhandler(connection, cursor, error_class, error_value)
  File "/home/user6/Project Dagster with dlt/.venv/lib/python3.12/site-packages/snowflake/connector/errors.py", line 210, in default_errorhandler
    raise error_class(
snowflake.connector.errors.ProgrammingError: 253006: File doesn't exist: ['/home/user6/.dlt/pipelines/postgres_to_snowflake/load/normalized/1753341887.5317843/started_jobs/items.5536d106e7.0.jsonl']

During handling of the above exception, another exception occurred:

Traceback (most recent call last):
  File "/home/user6/Project Dagster with dlt/.venv/lib/python3.12/site-packages/dlt/common/destination/client.py", line 406, in run_managed
    self.run()
  File "/home/user6/Project Dagster with dlt/.venv/lib/python3.12/site-packages/dlt/destinations/impl/snowflake/snowflake.py", line 109, in run
    self._sql_client.execute_sql(
  File "/home/user6/Project Dagster with dlt/.venv/lib/python3.12/site-packages/dlt/destinations/impl/snowflake/sql_client.py", line 116, in execute_sql
    with self.execute_query(sql, *args, **kwargs) as curr:
  File "/usr/lib/python3.12/contextlib.py", line 137, in __enter__
    return next(self.gen)
           ^^^^^^^^^^^^^^
  File "/home/user6/Project Dagster with dlt/.venv/lib/python3.12/site-packages/dlt/destinations/sql_client.py", line 445, in _wrap_gen
    raise self._make_database_exception(ex)
dlt.destinations.exceptions.DatabaseTransientException: 253006: File doesn't exist: ['/home/user6/.dlt/pipelines/postgres_to_snowflake/load/normalized/1753341887.5317843/started_jobs/items.5536d106e7.0.jsonl']
2025-07-24 12:25:16,058|[ERROR]|106547|124912329021120|dlt|load.py|w_run_job:247|Transient exception in job customers.66c1d05059.jsonl in file /home/user6/.dlt/pipelines/postgres_to_snowflake/load/normalized/1753341887.5317843/started_jobs/customers.66c1d05059.0.jsonl
Traceback (most recent call last):
  File "/home/user6/Project Dagster with dlt/.venv/lib/python3.12/site-packages/dlt/destinations/sql_client.py", line 443, in _wrap_gen
    return (yield from f(self, *args, **kwargs))
            ^^^^^^^^^^^^^^^^^^^^^^^^^^^^^^^^^^^
  File "/home/user6/Project Dagster with dlt/.venv/lib/python3.12/site-packages/dlt/destinations/impl/snowflake/sql_client.py", line 138, in execute_query
    raise outer
  File "/home/user6/Project Dagster with dlt/.venv/lib/python3.12/site-packages/dlt/destinations/impl/snowflake/sql_client.py", line 130, in execute_query
    curr.execute(query, db_args, num_statements=0)
  File "/home/user6/Project Dagster with dlt/.venv/lib/python3.12/site-packages/snowflake/connector/cursor.py", line 1090, in execute
    sf_file_transfer_agent.execute()
  File "/home/user6/Project Dagster with dlt/.venv/lib/python3.12/site-packages/snowflake/connector/file_transfer_agent.py", line 393, in execute
    self._init_file_metadata()
  File "/home/user6/Project Dagster with dlt/.venv/lib/python3.12/site-packages/snowflake/connector/file_transfer_agent.py", line 999, in _init_file_metadata
    Error.errorhandler_wrapper(
  File "/home/user6/Project Dagster with dlt/.venv/lib/python3.12/site-packages/snowflake/connector/errors.py", line 279, in errorhandler_wrapper
    handed_over = Error.hand_to_other_handler(
                  ^^^^^^^^^^^^^^^^^^^^^^^^^^^^
  File "/home/user6/Project Dagster with dlt/.venv/lib/python3.12/site-packages/snowflake/connector/errors.py", line 334, in hand_to_other_handler
    cursor.errorhandler(connection, cursor, error_class, error_value)
  File "/home/user6/Project Dagster with dlt/.venv/lib/python3.12/site-packages/snowflake/connector/errors.py", line 210, in default_errorhandler
    raise error_class(
snowflake.connector.errors.ProgrammingError: 253006: File doesn't exist: ['/home/user6/.dlt/pipelines/postgres_to_snowflake/load/normalized/1753341887.5317843/started_jobs/customers.66c1d05059.0.jsonl']

During handling of the above exception, another exception occurred:

Traceback (most recent call last):
  File "/home/user6/Project Dagster with dlt/.venv/lib/python3.12/site-packages/dlt/common/destination/client.py", line 406, in run_managed
    self.run()
  File "/home/user6/Project Dagster with dlt/.venv/lib/python3.12/site-packages/dlt/destinations/impl/snowflake/snowflake.py", line 109, in run
    self._sql_client.execute_sql(
  File "/home/user6/Project Dagster with dlt/.venv/lib/python3.12/site-packages/dlt/destinations/impl/snowflake/sql_client.py", line 116, in execute_sql
    with self.execute_query(sql, *args, **kwargs) as curr:
  File "/usr/lib/python3.12/contextlib.py", line 137, in __enter__
    return next(self.gen)
           ^^^^^^^^^^^^^^
  File "/home/user6/Project Dagster with dlt/.venv/lib/python3.12/site-packages/dlt/destinations/sql_client.py", line 445, in _wrap_gen
    raise self._make_database_exception(ex)
dlt.destinations.exceptions.DatabaseTransientException: 253006: File doesn't exist: ['/home/user6/.dlt/pipelines/postgres_to_snowflake/load/normalized/1753341887.5317843/started_jobs/customers.66c1d05059.0.jsonl']
2025-07-24 12:25:16,353|[ERROR]|106547|124912337413824|dlt|load.py|w_run_job:247|Transient exception in job orders.a9217293aa.jsonl in file /home/user6/.dlt/pipelines/postgres_to_snowflake/load/normalized/1753341887.5317843/started_jobs/orders.a9217293aa.0.jsonl
Traceback (most recent call last):
  File "/home/user6/Project Dagster with dlt/.venv/lib/python3.12/site-packages/dlt/destinations/sql_client.py", line 443, in _wrap_gen
    return (yield from f(self, *args, **kwargs))
            ^^^^^^^^^^^^^^^^^^^^^^^^^^^^^^^^^^^
  File "/home/user6/Project Dagster with dlt/.venv/lib/python3.12/site-packages/dlt/destinations/impl/snowflake/sql_client.py", line 138, in execute_query
    raise outer
  File "/home/user6/Project Dagster with dlt/.venv/lib/python3.12/site-packages/dlt/destinations/impl/snowflake/sql_client.py", line 130, in execute_query
    curr.execute(query, db_args, num_statements=0)
  File "/home/user6/Project Dagster with dlt/.venv/lib/python3.12/site-packages/snowflake/connector/cursor.py", line 1091, in execute
    data = sf_file_transfer_agent.result()
           ^^^^^^^^^^^^^^^^^^^^^^^^^^^^^^^
  File "/home/user6/Project Dagster with dlt/.venv/lib/python3.12/site-packages/snowflake/connector/file_transfer_agent.py", line 753, in result
    Error.errorhandler_wrapper(
  File "/home/user6/Project Dagster with dlt/.venv/lib/python3.12/site-packages/snowflake/connector/errors.py", line 279, in errorhandler_wrapper
    handed_over = Error.hand_to_other_handler(
                  ^^^^^^^^^^^^^^^^^^^^^^^^^^^^
  File "/home/user6/Project Dagster with dlt/.venv/lib/python3.12/site-packages/snowflake/connector/errors.py", line 334, in hand_to_other_handler
    cursor.errorhandler(connection, cursor, error_class, error_value)
  File "/home/user6/Project Dagster with dlt/.venv/lib/python3.12/site-packages/snowflake/connector/errors.py", line 210, in default_errorhandler
    raise error_class(
snowflake.connector.errors.OperationalError: 253003: While putting file(s) there was an error: 'FileNotFoundError(2, 'No such file or directory')', this might be caused by your access to the blob storage provider, or by Snowflake.

During handling of the above exception, another exception occurred:

Traceback (most recent call last):
  File "/home/user6/Project Dagster with dlt/.venv/lib/python3.12/site-packages/dlt/common/destination/client.py", line 406, in run_managed
    self.run()
  File "/home/user6/Project Dagster with dlt/.venv/lib/python3.12/site-packages/dlt/destinations/impl/snowflake/snowflake.py", line 109, in run
    self._sql_client.execute_sql(
  File "/home/user6/Project Dagster with dlt/.venv/lib/python3.12/site-packages/dlt/destinations/impl/snowflake/sql_client.py", line 116, in execute_sql
    with self.execute_query(sql, *args, **kwargs) as curr:
  File "/usr/lib/python3.12/contextlib.py", line 137, in __enter__
    return next(self.gen)
           ^^^^^^^^^^^^^^
  File "/home/user6/Project Dagster with dlt/.venv/lib/python3.12/site-packages/dlt/destinations/sql_client.py", line 445, in _wrap_gen
    raise self._make_database_exception(ex)
dlt.destinations.exceptions.DatabaseTransientException: 253003: While putting file(s) there was an error: 'FileNotFoundError(2, 'No such file or directory')', this might be caused by your access to the blob storage provider, or by Snowflake.
[32m2025-07-24 12:25:16 +0500[0m - dagster - [34mERROR[0m - [31m__ASSET_JOB - 381c75c1-f0c2-4294-8bbb-19f893d3a9a2 - 106547 - load_postgres_data - STEP_FAILURE - Execution of step "load_postgres_data" failed.

dagster._core.errors.DagsterExecutionStepExecutionError: Error occurred while executing op "load_postgres_data"::

dlt.pipeline.exceptions.PipelineStepFailed: Pipeline execution failed at `step=load` when processing package with `load_id=1753341887.5317843` with exception:

<class 'FileNotFoundError'>
[Errno 2] No such file or directory: '/home/user6/.dlt/pipelines/postgres_to_snowflake/load/normalized/1753341887.5317843/started_jobs/orders.a9217293aa.0.jsonl' -> '/home/user6/.dlt/pipelines/postgres_to_snowflake/load/normalized/1753341887.5317843/new_jobs/orders.a9217293aa.1.jsonl'

Stack Trace:
  File "/home/user6/Project Dagster with dlt/.venv/lib/python3.12/site-packages/dagster/_core/execution/plan/utils.py", line 57, in op_execution_error_boundary
    yield
  File "/home/user6/Project Dagster with dlt/.venv/lib/python3.12/site-packages/dagster/_utils/__init__.py", line 392, in iterate_with_context
    next_output = next(iterator)
                  ^^^^^^^^^^^^^^
  File "/home/user6/Project Dagster with dlt/.venv/lib/python3.12/site-packages/dagster/_core/execution/plan/compute_generator.py", line 137, in _coerce_op_compute_fn_to_iterator
    result = invoke_compute_fn(
             ^^^^^^^^^^^^^^^^^^
  File "/home/user6/Project Dagster with dlt/.venv/lib/python3.12/site-packages/dagster/_core/execution/plan/compute_generator.py", line 117, in invoke_compute_fn
    return fn(context, **args_to_pass) if context_arg_provided else fn(**args_to_pass)
                                                                    ^^^^^^^^^^^^^^^^^^
  File "/home/user6/Project Dagster with dlt/my_source/my-source/my_source/assets.py", line 25, in load_postgres_data
    load_info = pipeline.run(source, write_disposition="replace")
                ^^^^^^^^^^^^^^^^^^^^^^^^^^^^^^^^^^^^^^^^^^^^^^^^^
  File "/home/user6/Project Dagster with dlt/.venv/lib/python3.12/site-packages/dlt/pipeline/pipeline.py", line 231, in _wrap
    step_info = f(self, *args, **kwargs)
                ^^^^^^^^^^^^^^^^^^^^^^^^
  File "/home/user6/Project Dagster with dlt/.venv/lib/python3.12/site-packages/dlt/pipeline/pipeline.py", line 280, in _wrap
    return f(self, *args, **kwargs)
           ^^^^^^^^^^^^^^^^^^^^^^^^
  File "/home/user6/Project Dagster with dlt/.venv/lib/python3.12/site-packages/dlt/pipeline/pipeline.py", line 744, in run
    return self.load(destination, dataset_name, credentials=credentials)
           ^^^^^^^^^^^^^^^^^^^^^^^^^^^^^^^^^^^^^^^^^^^^^^^^^^^^^^^^^^^^^
  File "/home/user6/Project Dagster with dlt/.venv/lib/python3.12/site-packages/dlt/pipeline/pipeline.py", line 231, in _wrap
    step_info = f(self, *args, **kwargs)
                ^^^^^^^^^^^^^^^^^^^^^^^^
  File "/home/user6/Project Dagster with dlt/.venv/lib/python3.12/site-packages/dlt/pipeline/pipeline.py", line 171, in _wrap
    return f(self, *args, **kwargs)
           ^^^^^^^^^^^^^^^^^^^^^^^^
  File "/home/user6/Project Dagster with dlt/.venv/lib/python3.12/site-packages/dlt/pipeline/pipeline.py", line 280, in _wrap
    return f(self, *args, **kwargs)
           ^^^^^^^^^^^^^^^^^^^^^^^^
  File "/home/user6/Project Dagster with dlt/.venv/lib/python3.12/site-packages/dlt/pipeline/pipeline.py", line 607, in load
    raise PipelineStepFailed(

The above exception was caused by the following exception:
FileNotFoundError: [Errno 2] No such file or directory: '/home/user6/.dlt/pipelines/postgres_to_snowflake/load/normalized/1753341887.5317843/started_jobs/orders.a9217293aa.0.jsonl' -> '/home/user6/.dlt/pipelines/postgres_to_snowflake/load/normalized/1753341887.5317843/new_jobs/orders.a9217293aa.1.jsonl'

Stack Trace:
  File "/home/user6/Project Dagster with dlt/.venv/lib/python3.12/site-packages/dlt/pipeline/pipeline.py", line 601, in load
    runner.run_pool(load_step.config, load_step)
  File "/home/user6/Project Dagster with dlt/.venv/lib/python3.12/site-packages/dlt/common/runners/pool_runner.py", line 203, in run_pool
    while _run_func():
          ^^^^^^^^^^^
  File "/home/user6/Project Dagster with dlt/.venv/lib/python3.12/site-packages/dlt/common/runners/pool_runner.py", line 196, in _run_func
    run_metrics = run_f.run(cast(TExecutor, pool))
                  ^^^^^^^^^^^^^^^^^^^^^^^^^^^^^^^^
  File "/home/user6/Project Dagster with dlt/.venv/lib/python3.12/site-packages/dlt/load/load.py", line 638, in run
    self.load_single_package(load_id, schema)
  File "/home/user6/Project Dagster with dlt/.venv/lib/python3.12/site-packages/dlt/load/load.py", line 571, in load_single_package
    running_jobs, finalized_jobs, new_pending_exception = self.complete_jobs(
                                                          ^^^^^^^^^^^^^^^^^^^
  File "/home/user6/Project Dagster with dlt/.venv/lib/python3.12/site-packages/dlt/load/load.py", line 429, in complete_jobs
    self.load_storage.normalized_packages.retry_job(load_id, job.file_name())
  File "/home/user6/Project Dagster with dlt/.venv/lib/python3.12/site-packages/dlt/common/storages/load_package.py", line 449, in retry_job
    return self._move_job(
           ^^^^^^^^^^^^^^^
  File "/home/user6/Project Dagster with dlt/.venv/lib/python3.12/site-packages/dlt/common/storages/load_package.py", line 704, in _move_job
    self.storage.atomic_rename(
  File "/home/user6/Project Dagster with dlt/.venv/lib/python3.12/site-packages/dlt/common/storages/file_storage.py", line 185, in atomic_rename
    os.rename(self.make_full_path(from_relative_path), self.make_full_path(to_relative_path))
[0m
